[0m09:44:51.037645 [debug] [MainThread]: Sending event: {'category': 'dbt', 'action': 'invocation', 'label': 'start', 'context': [<snowplow_tracker.self_describing_json.SelfDescribingJson object at 0x1049a0e80>, <snowplow_tracker.self_describing_json.SelfDescribingJson object at 0x106e9f5b0>, <snowplow_tracker.self_describing_json.SelfDescribingJson object at 0x106e9e890>]}


============================== 09:44:51.040515 | f3049391-da8c-4b4c-9a9c-73c899ce47ce ==============================
[0m09:44:51.040515 [info ] [MainThread]: Running with dbt=1.7.1
[0m09:44:51.040878 [debug] [MainThread]: running dbt with arguments {'printer_width': '80', 'indirect_selection': 'eager', 'log_cache_events': 'False', 'write_json': 'True', 'partial_parse': 'True', 'cache_selected_only': 'False', 'profiles_dir': '/Users/valentin/.dbt', 'debug': 'False', 'warn_error': 'None', 'log_path': 'logs', 'fail_fast': 'False', 'version_check': 'True', 'use_colors': 'True', 'use_experimental_parser': 'False', 'no_print': 'None', 'quiet': 'False', 'warn_error_options': 'WarnErrorOptions(include=[], exclude=[])', 'static_parser': 'True', 'introspect': 'True', 'invocation_command': 'dbt run', 'target_path': 'None', 'log_format': 'default', 'send_anonymous_usage_stats': 'True'}
[0m09:44:51.041240 [error] [MainThread]: Encountered an error:
Runtime Error
  No dbt_project.yml found at expected path /Users/valentin/Github/data-gcp/dbt_project.yml
  Verify that each entry within packages.yml (and their transitive dependencies) contains a file named dbt_project.yml
  
[0m09:44:51.069317 [debug] [MainThread]: Resource report: {"command_name": "run", "command_wall_clock_time": 0.06486908, "process_user_time": 1.143986, "process_kernel_time": 0.11312, "process_mem_max_rss": "98123776", "command_success": false, "process_in_blocks": "0", "process_out_blocks": "0"}
[0m09:44:51.069801 [debug] [MainThread]: Command `dbt run` failed at 09:44:51.069709 after 0.07 seconds
[0m09:44:51.070068 [debug] [MainThread]: Sending event: {'category': 'dbt', 'action': 'invocation', 'label': 'end', 'context': [<snowplow_tracker.self_describing_json.SelfDescribingJson object at 0x1049a0e80>, <snowplow_tracker.self_describing_json.SelfDescribingJson object at 0x106e9f550>, <snowplow_tracker.self_describing_json.SelfDescribingJson object at 0x106e9f7c0>]}
[0m09:44:51.070324 [debug] [MainThread]: Flushing usage events
[0m10:33:39.464501 [debug] [MainThread]: Sending event: {'category': 'dbt', 'action': 'invocation', 'label': 'start', 'context': [<snowplow_tracker.self_describing_json.SelfDescribingJson object at 0x106a19240>, <snowplow_tracker.self_describing_json.SelfDescribingJson object at 0x1138cd780>, <snowplow_tracker.self_describing_json.SelfDescribingJson object at 0x1138ccac0>]}


============================== 10:33:39.473865 | bd1287d1-cc93-4749-b0a0-e430ba0e6391 ==============================
[0m10:33:39.473865 [info ] [MainThread]: Running with dbt=1.7.1
[0m10:33:39.476923 [debug] [MainThread]: running dbt with arguments {'printer_width': '80', 'indirect_selection': 'eager', 'write_json': 'True', 'log_cache_events': 'False', 'partial_parse': 'True', 'cache_selected_only': 'False', 'warn_error': 'None', 'version_check': 'True', 'profiles_dir': '/Users/valentin/.dbt', 'log_path': 'logs', 'debug': 'False', 'fail_fast': 'False', 'use_colors': 'True', 'use_experimental_parser': 'False', 'no_print': 'None', 'quiet': 'False', 'warn_error_options': 'WarnErrorOptions(include=[], exclude=[])', 'static_parser': 'True', 'log_format': 'default', 'invocation_command': 'dbt run -s applicative_database_booking_history', 'target_path': 'None', 'introspect': 'True', 'send_anonymous_usage_stats': 'True'}
[0m10:33:39.478390 [error] [MainThread]: Encountered an error:
Runtime Error
  No dbt_project.yml found at expected path /Users/valentin/Github/data-gcp/dbt_project.yml
  Verify that each entry within packages.yml (and their transitive dependencies) contains a file named dbt_project.yml
  
[0m10:33:39.483365 [debug] [MainThread]: Resource report: {"command_name": "run", "command_wall_clock_time": 0.11096609, "process_user_time": 1.784278, "process_kernel_time": 0.285168, "process_mem_max_rss": "94552064", "command_success": false, "process_in_blocks": "0", "process_out_blocks": "0"}
[0m10:33:39.485370 [debug] [MainThread]: Command `dbt run` failed at 10:33:39.484702 after 0.11 seconds
[0m10:33:39.486789 [debug] [MainThread]: Sending event: {'category': 'dbt', 'action': 'invocation', 'label': 'end', 'context': [<snowplow_tracker.self_describing_json.SelfDescribingJson object at 0x106a19240>, <snowplow_tracker.self_describing_json.SelfDescribingJson object at 0x1138cdb70>, <snowplow_tracker.self_describing_json.SelfDescribingJson object at 0x1138cd9c0>]}
[0m10:33:39.487909 [debug] [MainThread]: Flushing usage events
