import os

from google.auth.exceptions import DefaultCredentialsError
from google.cloud import secretmanager

PROJECT_NAME = os.environ.get("PROJECT_NAME")
ENVIRONMENT_SHORT_NAME = os.environ.get("ENV_SHORT_NAME")
ANALYTICS_DATASET = f"analytics_{ENVIRONMENT_SHORT_NAME}"
CLEAN_DATASET = f"clean_{ENVIRONMENT_SHORT_NAME}"
INT_METABASE_DATASET = f"int_metabase_{ENVIRONMENT_SHORT_NAME}"
# METABASE_API_USERNAME = os.environ.get("METABASE_API_USERNAME")
# METABASE_HOST = os.environ.get("METABASE_HOST")
METABASE_API_USERNAME = "metabase-data-bot@passculture.app"

parent_folder_to_archive = ["interne", "operationnel"]
limit_inactivity_in_days = 100
max_cards_to_archive = 50


def access_secret_data(project_id, secret_id, default=None):
    try:
        client = secretmanager.SecretManagerServiceClient()
        name = f"projects/{project_id}/secrets/{secret_id}/versions/latest"
        response = client.access_secret_version(request={"name": name})
        return response.payload.data.decode("UTF-8")
    except DefaultCredentialsError:
        return default
